<?xml version="1.0" encoding="UTF-8"?>
<!-- Generated by org.testng.reporters.JUnitReportReporter -->
<testsuite skipped="0" hostname="LAPTOP-RRO4KGR3" name="com.w2a.testcases.LoginTest" tests="2" failures="1" timestamp="02 Jul 2021 05:43:03 GMT" time="9.262" errors="0">
  <testcase name="loginasnewbankmanaer" time="0.119" classname="com.w2a.testcases.LoginTest"/>
  <testcase name="loginasBankManahger" time="9.143" classname="com.w2a.testcases.LoginTest">
    <failure type="java.lang.AssertionError" message="The following asserts failed:
	intentially failing the test">
      <![CDATA[java.lang.AssertionError: The following asserts failed:
	intentially failing the test
	at org.testng.asserts.SoftAssert.assertAll(SoftAssert.java:43)
	at com.w2a.testcases.LoginTest.loginasBankManahger(LoginTest.java:20)
	at sun.reflect.NativeMethodAccessorImpl.invoke0(Native Method)
	at sun.reflect.NativeMethodAccessorImpl.invoke(NativeMethodAccessorImpl.java:62)
	at sun.reflect.DelegatingMethodAccessorImpl.invoke(DelegatingMethodAccessorImpl.java:43)
	at java.lang.reflect.Method.invoke(Method.java:498)
	at org.testng.internal.MethodInvocationHelper.invokeMethod(MethodInvocationHelper.java:108)
	at org.testng.internal.Invoker.invokeMethod(Invoker.java:661)
	at org.testng.internal.Invoker.invokeTestMethod(Invoker.java:869)
	at org.testng.internal.Invoker.invokeTestMethods(Invoker.java:1193)
	at org.testng.internal.TestMethodWorker.invokeTestMethods(TestMethodWorker.java:126)
	at org.testng.internal.TestMethodWorker.run(TestMethodWorker.java:109)
	at org.testng.TestRunner.privateRun(TestRunner.java:744)
	at org.testng.TestRunner.run(TestRunner.java:602)
	at org.testng.SuiteRunner.runTest(SuiteRunner.java:380)
	at org.testng.SuiteRunner.runSequentially(SuiteRunner.java:375)
	at org.testng.SuiteRunner.privateRun(SuiteRunner.java:340)
	at org.testng.SuiteRunner.run(SuiteRunner.java:289)
	at org.testng.SuiteRunnerWorker.runSuite(SuiteRunnerWorker.java:52)
	at org.testng.SuiteRunnerWorker.run(SuiteRunnerWorker.java:86)
	at org.testng.TestNG.runSuitesSequentially(TestNG.java:1301)
	at org.testng.TestNG.runSuitesLocally(TestNG.java:1226)
	at org.testng.TestNG.runSuites(TestNG.java:1144)
	at org.testng.TestNG.run(TestNG.java:1115)
	at org.apache.maven.surefire.testng.TestNGExecutor.run(TestNGExecutor.java:295)
	at org.apache.maven.surefire.testng.TestNGXmlTestSuite.execute(TestNGXmlTestSuite.java:84)
	at org.apache.maven.surefire.testng.TestNGProvider.invoke(TestNGProvider.java:90)
	at org.apache.maven.surefire.booter.ForkedBooter.invokeProviderInSameClassLoader(ForkedBooter.java:203)
	at org.apache.maven.surefire.booter.ForkedBooter.runSuitesInProcess(ForkedBooter.java:155)
	at org.apache.maven.surefire.booter.ForkedBooter.main(ForkedBooter.java:103)
]]>
    </failure>
  </testcase> <!-- loginasBankManahger -->
</testsuite> <!-- com.w2a.testcases.LoginTest -->
